{
 "cells": [
  {
   "cell_type": "code",
   "execution_count": 20,
   "id": "3456b127",
   "metadata": {},
   "outputs": [
    {
     "name": "stdout",
     "output_type": "stream",
     "text": [
      "The autoreload extension is already loaded. To reload it, use:\n",
      "  %reload_ext autoreload\n"
     ]
    }
   ],
   "source": [
    "%load_ext autoreload\n",
    "%autoreload 2"
   ]
  },
  {
   "cell_type": "code",
   "execution_count": 34,
   "id": "9718f39a",
   "metadata": {},
   "outputs": [],
   "source": [
    "import tensorflow as tf\n",
    "from scipy.stats import pearsonr"
   ]
  },
  {
   "cell_type": "code",
   "execution_count": 35,
   "id": "0bc4a1fc",
   "metadata": {},
   "outputs": [],
   "source": [
    "import sys\n",
    "sys.path.append('..')\n",
    "from dataset import batcher"
   ]
  },
  {
   "cell_type": "code",
   "execution_count": 46,
   "id": "5fa6bb11",
   "metadata": {},
   "outputs": [],
   "source": [
    "MODEL_DIR = '../saved_models/'\n",
    "LR_RATE = 0.001\n",
    "OPT = tf.keras.optimizers.Adam(learning_rate=LR_RATE)\n",
    "LOSS = 'MeanSquaredError'\n",
    "METRICS = ['RootMeanSquaredError']"
   ]
  },
  {
   "cell_type": "code",
   "execution_count": 63,
   "id": "0c6bda34",
   "metadata": {},
   "outputs": [],
   "source": [
    "# Load model\n",
    "experiments = ['imagery_sample_vgg_regression']\n",
    "\n",
    "def load_model_from_dir(model_name):\n",
    "    model_path = MODEL_DIR + model_name + '.h5'\n",
    "    print(model_path)\n",
    "    model = tf.keras.models.load_model(model_path, compile=False)\n",
    "    \n",
    "    return model"
   ]
  },
  {
   "cell_type": "code",
   "execution_count": 64,
   "id": "5bc12bc1",
   "metadata": {},
   "outputs": [],
   "source": [
    "# Get test split\n",
    "test_batcher = batcher.Batcher(bucket=False, shuffle=False, split='test').get_dataset()"
   ]
  },
  {
   "cell_type": "code",
   "execution_count": 65,
   "id": "58e819da",
   "metadata": {},
   "outputs": [
    {
     "name": "stdout",
     "output_type": "stream",
     "text": [
      "../saved_models/imagery_sample_vgg_regression.h5\n"
     ]
    },
    {
     "name": "stderr",
     "output_type": "stream",
     "text": [
      "2023-01-28 15:30:29.362384: I tensorflow/core/grappler/optimizers/custom_graph_optimizer_registry.cc:114] Plugin optimizer for device_type GPU is enabled.\n"
     ]
    },
    {
     "ename": "NotFoundError",
     "evalue": "Graph execution error:\n\nDetected at node 'IteratorGetNext' defined at (most recent call last):\n    File \"/Users/omshah/opt/anaconda3/envs/pypoverty38/lib/python3.8/runpy.py\", line 194, in _run_module_as_main\n      return _run_code(code, main_globals, None,\n    File \"/Users/omshah/opt/anaconda3/envs/pypoverty38/lib/python3.8/runpy.py\", line 87, in _run_code\n      exec(code, run_globals)\n    File \"/Users/omshah/.local/lib/python3.8/site-packages/ipykernel_launcher.py\", line 17, in <module>\n      app.launch_new_instance()\n    File \"/Users/omshah/.local/lib/python3.8/site-packages/traitlets/config/application.py\", line 978, in launch_instance\n      app.start()\n    File \"/Users/omshah/.local/lib/python3.8/site-packages/ipykernel/kernelapp.py\", line 712, in start\n      self.io_loop.start()\n    File \"/Users/omshah/.local/lib/python3.8/site-packages/tornado/platform/asyncio.py\", line 215, in start\n      self.asyncio_loop.run_forever()\n    File \"/Users/omshah/opt/anaconda3/envs/pypoverty38/lib/python3.8/asyncio/base_events.py\", line 570, in run_forever\n      self._run_once()\n    File \"/Users/omshah/opt/anaconda3/envs/pypoverty38/lib/python3.8/asyncio/base_events.py\", line 1859, in _run_once\n      handle._run()\n    File \"/Users/omshah/opt/anaconda3/envs/pypoverty38/lib/python3.8/asyncio/events.py\", line 81, in _run\n      self._context.run(self._callback, *self._args)\n    File \"/Users/omshah/.local/lib/python3.8/site-packages/ipykernel/kernelbase.py\", line 510, in dispatch_queue\n      await self.process_one()\n    File \"/Users/omshah/.local/lib/python3.8/site-packages/ipykernel/kernelbase.py\", line 499, in process_one\n      await dispatch(*args)\n    File \"/Users/omshah/.local/lib/python3.8/site-packages/ipykernel/kernelbase.py\", line 406, in dispatch_shell\n      await result\n    File \"/Users/omshah/.local/lib/python3.8/site-packages/ipykernel/kernelbase.py\", line 730, in execute_request\n      reply_content = await reply_content\n    File \"/Users/omshah/.local/lib/python3.8/site-packages/ipykernel/ipkernel.py\", line 383, in do_execute\n      res = shell.run_cell(\n    File \"/Users/omshah/.local/lib/python3.8/site-packages/ipykernel/zmqshell.py\", line 528, in run_cell\n      return super().run_cell(*args, **kwargs)\n    File \"/Users/omshah/.local/lib/python3.8/site-packages/IPython/core/interactiveshell.py\", line 2885, in run_cell\n      result = self._run_cell(\n    File \"/Users/omshah/.local/lib/python3.8/site-packages/IPython/core/interactiveshell.py\", line 2940, in _run_cell\n      return runner(coro)\n    File \"/Users/omshah/.local/lib/python3.8/site-packages/IPython/core/async_helpers.py\", line 129, in _pseudo_sync_runner\n      coro.send(None)\n    File \"/Users/omshah/.local/lib/python3.8/site-packages/IPython/core/interactiveshell.py\", line 3139, in run_cell_async\n      has_raised = await self.run_ast_nodes(code_ast.body, cell_name,\n    File \"/Users/omshah/.local/lib/python3.8/site-packages/IPython/core/interactiveshell.py\", line 3318, in run_ast_nodes\n      if await self.run_code(code, result, async_=asy):\n    File \"/Users/omshah/.local/lib/python3.8/site-packages/IPython/core/interactiveshell.py\", line 3378, in run_code\n      exec(code_obj, self.user_global_ns, self.user_ns)\n    File \"/var/folders/yw/3z56n_vx4vq9g05qrxzrr4m40000gn/T/ipykernel_19104/2308989814.py\", line 8, in <module>\n      consumption_predicts = trained_model.predict(test_batcher, steps=652)\n    File \"/Users/omshah/opt/anaconda3/envs/pypoverty38/lib/python3.8/site-packages/keras/utils/traceback_utils.py\", line 65, in error_handler\n      return fn(*args, **kwargs)\n    File \"/Users/omshah/opt/anaconda3/envs/pypoverty38/lib/python3.8/site-packages/keras/engine/training.py\", line 2253, in predict\n      tmp_batch_outputs = self.predict_function(iterator)\n    File \"/Users/omshah/opt/anaconda3/envs/pypoverty38/lib/python3.8/site-packages/keras/engine/training.py\", line 2041, in predict_function\n      return step_function(self, iterator)\n    File \"/Users/omshah/opt/anaconda3/envs/pypoverty38/lib/python3.8/site-packages/keras/engine/training.py\", line 2026, in step_function\n      data = next(iterator)\nNode: 'IteratorGetNext'\nDetected at node 'IteratorGetNext' defined at (most recent call last):\n    File \"/Users/omshah/opt/anaconda3/envs/pypoverty38/lib/python3.8/runpy.py\", line 194, in _run_module_as_main\n      return _run_code(code, main_globals, None,\n    File \"/Users/omshah/opt/anaconda3/envs/pypoverty38/lib/python3.8/runpy.py\", line 87, in _run_code\n      exec(code, run_globals)\n    File \"/Users/omshah/.local/lib/python3.8/site-packages/ipykernel_launcher.py\", line 17, in <module>\n      app.launch_new_instance()\n    File \"/Users/omshah/.local/lib/python3.8/site-packages/traitlets/config/application.py\", line 978, in launch_instance\n      app.start()\n    File \"/Users/omshah/.local/lib/python3.8/site-packages/ipykernel/kernelapp.py\", line 712, in start\n      self.io_loop.start()\n    File \"/Users/omshah/.local/lib/python3.8/site-packages/tornado/platform/asyncio.py\", line 215, in start\n      self.asyncio_loop.run_forever()\n    File \"/Users/omshah/opt/anaconda3/envs/pypoverty38/lib/python3.8/asyncio/base_events.py\", line 570, in run_forever\n      self._run_once()\n    File \"/Users/omshah/opt/anaconda3/envs/pypoverty38/lib/python3.8/asyncio/base_events.py\", line 1859, in _run_once\n      handle._run()\n    File \"/Users/omshah/opt/anaconda3/envs/pypoverty38/lib/python3.8/asyncio/events.py\", line 81, in _run\n      self._context.run(self._callback, *self._args)\n    File \"/Users/omshah/.local/lib/python3.8/site-packages/ipykernel/kernelbase.py\", line 510, in dispatch_queue\n      await self.process_one()\n    File \"/Users/omshah/.local/lib/python3.8/site-packages/ipykernel/kernelbase.py\", line 499, in process_one\n      await dispatch(*args)\n    File \"/Users/omshah/.local/lib/python3.8/site-packages/ipykernel/kernelbase.py\", line 406, in dispatch_shell\n      await result\n    File \"/Users/omshah/.local/lib/python3.8/site-packages/ipykernel/kernelbase.py\", line 730, in execute_request\n      reply_content = await reply_content\n    File \"/Users/omshah/.local/lib/python3.8/site-packages/ipykernel/ipkernel.py\", line 383, in do_execute\n      res = shell.run_cell(\n    File \"/Users/omshah/.local/lib/python3.8/site-packages/ipykernel/zmqshell.py\", line 528, in run_cell\n      return super().run_cell(*args, **kwargs)\n    File \"/Users/omshah/.local/lib/python3.8/site-packages/IPython/core/interactiveshell.py\", line 2885, in run_cell\n      result = self._run_cell(\n    File \"/Users/omshah/.local/lib/python3.8/site-packages/IPython/core/interactiveshell.py\", line 2940, in _run_cell\n      return runner(coro)\n    File \"/Users/omshah/.local/lib/python3.8/site-packages/IPython/core/async_helpers.py\", line 129, in _pseudo_sync_runner\n      coro.send(None)\n    File \"/Users/omshah/.local/lib/python3.8/site-packages/IPython/core/interactiveshell.py\", line 3139, in run_cell_async\n      has_raised = await self.run_ast_nodes(code_ast.body, cell_name,\n    File \"/Users/omshah/.local/lib/python3.8/site-packages/IPython/core/interactiveshell.py\", line 3318, in run_ast_nodes\n      if await self.run_code(code, result, async_=asy):\n    File \"/Users/omshah/.local/lib/python3.8/site-packages/IPython/core/interactiveshell.py\", line 3378, in run_code\n      exec(code_obj, self.user_global_ns, self.user_ns)\n    File \"/var/folders/yw/3z56n_vx4vq9g05qrxzrr4m40000gn/T/ipykernel_19104/2308989814.py\", line 8, in <module>\n      consumption_predicts = trained_model.predict(test_batcher, steps=652)\n    File \"/Users/omshah/opt/anaconda3/envs/pypoverty38/lib/python3.8/site-packages/keras/utils/traceback_utils.py\", line 65, in error_handler\n      return fn(*args, **kwargs)\n    File \"/Users/omshah/opt/anaconda3/envs/pypoverty38/lib/python3.8/site-packages/keras/engine/training.py\", line 2253, in predict\n      tmp_batch_outputs = self.predict_function(iterator)\n    File \"/Users/omshah/opt/anaconda3/envs/pypoverty38/lib/python3.8/site-packages/keras/engine/training.py\", line 2041, in predict_function\n      return step_function(self, iterator)\n    File \"/Users/omshah/opt/anaconda3/envs/pypoverty38/lib/python3.8/site-packages/keras/engine/training.py\", line 2026, in step_function\n      data = next(iterator)\nNode: 'IteratorGetNext'\n2 root error(s) found.\n  (0) NOT_FOUND:  data/lsms_tfrecords/ethiopia_89_7.tfrecord; No such file or directory\n\t [[{{node IteratorGetNext}}]]\n\t [[IteratorGetNext/_2]]\n  (1) NOT_FOUND:  data/lsms_tfrecords/ethiopia_89_7.tfrecord; No such file or directory\n\t [[{{node IteratorGetNext}}]]\n0 successful operations.\n0 derived errors ignored. [Op:__inference_predict_function_10750]",
     "output_type": "error",
     "traceback": [
      "\u001b[0;31m---------------------------------------------------------------------------\u001b[0m",
      "\u001b[0;31mNotFoundError\u001b[0m                             Traceback (most recent call last)",
      "Cell \u001b[0;32mIn [65], line 8\u001b[0m\n\u001b[1;32m      2\u001b[0m trained_model \u001b[38;5;241m=\u001b[39m load_model_from_dir(experiments[\u001b[38;5;241m0\u001b[39m])\n\u001b[1;32m      3\u001b[0m trained_model\u001b[38;5;241m.\u001b[39mcompile(\n\u001b[1;32m      4\u001b[0m             loss\u001b[38;5;241m=\u001b[39mLOSS,\n\u001b[1;32m      5\u001b[0m             optimizer\u001b[38;5;241m=\u001b[39mOPT,\n\u001b[1;32m      6\u001b[0m             metrics\u001b[38;5;241m=\u001b[39mMETRICS,\n\u001b[1;32m      7\u001b[0m         )\n\u001b[0;32m----> 8\u001b[0m consumption_predicts \u001b[38;5;241m=\u001b[39m \u001b[43mtrained_model\u001b[49m\u001b[38;5;241;43m.\u001b[39;49m\u001b[43mpredict\u001b[49m\u001b[43m(\u001b[49m\u001b[43mtest_batcher\u001b[49m\u001b[43m,\u001b[49m\u001b[43m \u001b[49m\u001b[43msteps\u001b[49m\u001b[38;5;241;43m=\u001b[39;49m\u001b[38;5;241;43m652\u001b[39;49m\u001b[43m)\u001b[49m\n",
      "File \u001b[0;32m~/opt/anaconda3/envs/pypoverty38/lib/python3.8/site-packages/keras/utils/traceback_utils.py:70\u001b[0m, in \u001b[0;36mfilter_traceback.<locals>.error_handler\u001b[0;34m(*args, **kwargs)\u001b[0m\n\u001b[1;32m     67\u001b[0m     filtered_tb \u001b[38;5;241m=\u001b[39m _process_traceback_frames(e\u001b[38;5;241m.\u001b[39m__traceback__)\n\u001b[1;32m     68\u001b[0m     \u001b[38;5;66;03m# To get the full stack trace, call:\u001b[39;00m\n\u001b[1;32m     69\u001b[0m     \u001b[38;5;66;03m# `tf.debugging.disable_traceback_filtering()`\u001b[39;00m\n\u001b[0;32m---> 70\u001b[0m     \u001b[38;5;28;01mraise\u001b[39;00m e\u001b[38;5;241m.\u001b[39mwith_traceback(filtered_tb) \u001b[38;5;28;01mfrom\u001b[39;00m \u001b[38;5;28mNone\u001b[39m\n\u001b[1;32m     71\u001b[0m \u001b[38;5;28;01mfinally\u001b[39;00m:\n\u001b[1;32m     72\u001b[0m     \u001b[38;5;28;01mdel\u001b[39;00m filtered_tb\n",
      "File \u001b[0;32m~/opt/anaconda3/envs/pypoverty38/lib/python3.8/site-packages/tensorflow/python/eager/execute.py:54\u001b[0m, in \u001b[0;36mquick_execute\u001b[0;34m(op_name, num_outputs, inputs, attrs, ctx, name)\u001b[0m\n\u001b[1;32m     52\u001b[0m \u001b[38;5;28;01mtry\u001b[39;00m:\n\u001b[1;32m     53\u001b[0m   ctx\u001b[38;5;241m.\u001b[39mensure_initialized()\n\u001b[0;32m---> 54\u001b[0m   tensors \u001b[38;5;241m=\u001b[39m pywrap_tfe\u001b[38;5;241m.\u001b[39mTFE_Py_Execute(ctx\u001b[38;5;241m.\u001b[39m_handle, device_name, op_name,\n\u001b[1;32m     55\u001b[0m                                       inputs, attrs, num_outputs)\n\u001b[1;32m     56\u001b[0m \u001b[38;5;28;01mexcept\u001b[39;00m core\u001b[38;5;241m.\u001b[39m_NotOkStatusException \u001b[38;5;28;01mas\u001b[39;00m e:\n\u001b[1;32m     57\u001b[0m   \u001b[38;5;28;01mif\u001b[39;00m name \u001b[38;5;129;01mis\u001b[39;00m \u001b[38;5;129;01mnot\u001b[39;00m \u001b[38;5;28;01mNone\u001b[39;00m:\n",
      "\u001b[0;31mNotFoundError\u001b[0m: Graph execution error:\n\nDetected at node 'IteratorGetNext' defined at (most recent call last):\n    File \"/Users/omshah/opt/anaconda3/envs/pypoverty38/lib/python3.8/runpy.py\", line 194, in _run_module_as_main\n      return _run_code(code, main_globals, None,\n    File \"/Users/omshah/opt/anaconda3/envs/pypoverty38/lib/python3.8/runpy.py\", line 87, in _run_code\n      exec(code, run_globals)\n    File \"/Users/omshah/.local/lib/python3.8/site-packages/ipykernel_launcher.py\", line 17, in <module>\n      app.launch_new_instance()\n    File \"/Users/omshah/.local/lib/python3.8/site-packages/traitlets/config/application.py\", line 978, in launch_instance\n      app.start()\n    File \"/Users/omshah/.local/lib/python3.8/site-packages/ipykernel/kernelapp.py\", line 712, in start\n      self.io_loop.start()\n    File \"/Users/omshah/.local/lib/python3.8/site-packages/tornado/platform/asyncio.py\", line 215, in start\n      self.asyncio_loop.run_forever()\n    File \"/Users/omshah/opt/anaconda3/envs/pypoverty38/lib/python3.8/asyncio/base_events.py\", line 570, in run_forever\n      self._run_once()\n    File \"/Users/omshah/opt/anaconda3/envs/pypoverty38/lib/python3.8/asyncio/base_events.py\", line 1859, in _run_once\n      handle._run()\n    File \"/Users/omshah/opt/anaconda3/envs/pypoverty38/lib/python3.8/asyncio/events.py\", line 81, in _run\n      self._context.run(self._callback, *self._args)\n    File \"/Users/omshah/.local/lib/python3.8/site-packages/ipykernel/kernelbase.py\", line 510, in dispatch_queue\n      await self.process_one()\n    File \"/Users/omshah/.local/lib/python3.8/site-packages/ipykernel/kernelbase.py\", line 499, in process_one\n      await dispatch(*args)\n    File \"/Users/omshah/.local/lib/python3.8/site-packages/ipykernel/kernelbase.py\", line 406, in dispatch_shell\n      await result\n    File \"/Users/omshah/.local/lib/python3.8/site-packages/ipykernel/kernelbase.py\", line 730, in execute_request\n      reply_content = await reply_content\n    File \"/Users/omshah/.local/lib/python3.8/site-packages/ipykernel/ipkernel.py\", line 383, in do_execute\n      res = shell.run_cell(\n    File \"/Users/omshah/.local/lib/python3.8/site-packages/ipykernel/zmqshell.py\", line 528, in run_cell\n      return super().run_cell(*args, **kwargs)\n    File \"/Users/omshah/.local/lib/python3.8/site-packages/IPython/core/interactiveshell.py\", line 2885, in run_cell\n      result = self._run_cell(\n    File \"/Users/omshah/.local/lib/python3.8/site-packages/IPython/core/interactiveshell.py\", line 2940, in _run_cell\n      return runner(coro)\n    File \"/Users/omshah/.local/lib/python3.8/site-packages/IPython/core/async_helpers.py\", line 129, in _pseudo_sync_runner\n      coro.send(None)\n    File \"/Users/omshah/.local/lib/python3.8/site-packages/IPython/core/interactiveshell.py\", line 3139, in run_cell_async\n      has_raised = await self.run_ast_nodes(code_ast.body, cell_name,\n    File \"/Users/omshah/.local/lib/python3.8/site-packages/IPython/core/interactiveshell.py\", line 3318, in run_ast_nodes\n      if await self.run_code(code, result, async_=asy):\n    File \"/Users/omshah/.local/lib/python3.8/site-packages/IPython/core/interactiveshell.py\", line 3378, in run_code\n      exec(code_obj, self.user_global_ns, self.user_ns)\n    File \"/var/folders/yw/3z56n_vx4vq9g05qrxzrr4m40000gn/T/ipykernel_19104/2308989814.py\", line 8, in <module>\n      consumption_predicts = trained_model.predict(test_batcher, steps=652)\n    File \"/Users/omshah/opt/anaconda3/envs/pypoverty38/lib/python3.8/site-packages/keras/utils/traceback_utils.py\", line 65, in error_handler\n      return fn(*args, **kwargs)\n    File \"/Users/omshah/opt/anaconda3/envs/pypoverty38/lib/python3.8/site-packages/keras/engine/training.py\", line 2253, in predict\n      tmp_batch_outputs = self.predict_function(iterator)\n    File \"/Users/omshah/opt/anaconda3/envs/pypoverty38/lib/python3.8/site-packages/keras/engine/training.py\", line 2041, in predict_function\n      return step_function(self, iterator)\n    File \"/Users/omshah/opt/anaconda3/envs/pypoverty38/lib/python3.8/site-packages/keras/engine/training.py\", line 2026, in step_function\n      data = next(iterator)\nNode: 'IteratorGetNext'\nDetected at node 'IteratorGetNext' defined at (most recent call last):\n    File \"/Users/omshah/opt/anaconda3/envs/pypoverty38/lib/python3.8/runpy.py\", line 194, in _run_module_as_main\n      return _run_code(code, main_globals, None,\n    File \"/Users/omshah/opt/anaconda3/envs/pypoverty38/lib/python3.8/runpy.py\", line 87, in _run_code\n      exec(code, run_globals)\n    File \"/Users/omshah/.local/lib/python3.8/site-packages/ipykernel_launcher.py\", line 17, in <module>\n      app.launch_new_instance()\n    File \"/Users/omshah/.local/lib/python3.8/site-packages/traitlets/config/application.py\", line 978, in launch_instance\n      app.start()\n    File \"/Users/omshah/.local/lib/python3.8/site-packages/ipykernel/kernelapp.py\", line 712, in start\n      self.io_loop.start()\n    File \"/Users/omshah/.local/lib/python3.8/site-packages/tornado/platform/asyncio.py\", line 215, in start\n      self.asyncio_loop.run_forever()\n    File \"/Users/omshah/opt/anaconda3/envs/pypoverty38/lib/python3.8/asyncio/base_events.py\", line 570, in run_forever\n      self._run_once()\n    File \"/Users/omshah/opt/anaconda3/envs/pypoverty38/lib/python3.8/asyncio/base_events.py\", line 1859, in _run_once\n      handle._run()\n    File \"/Users/omshah/opt/anaconda3/envs/pypoverty38/lib/python3.8/asyncio/events.py\", line 81, in _run\n      self._context.run(self._callback, *self._args)\n    File \"/Users/omshah/.local/lib/python3.8/site-packages/ipykernel/kernelbase.py\", line 510, in dispatch_queue\n      await self.process_one()\n    File \"/Users/omshah/.local/lib/python3.8/site-packages/ipykernel/kernelbase.py\", line 499, in process_one\n      await dispatch(*args)\n    File \"/Users/omshah/.local/lib/python3.8/site-packages/ipykernel/kernelbase.py\", line 406, in dispatch_shell\n      await result\n    File \"/Users/omshah/.local/lib/python3.8/site-packages/ipykernel/kernelbase.py\", line 730, in execute_request\n      reply_content = await reply_content\n    File \"/Users/omshah/.local/lib/python3.8/site-packages/ipykernel/ipkernel.py\", line 383, in do_execute\n      res = shell.run_cell(\n    File \"/Users/omshah/.local/lib/python3.8/site-packages/ipykernel/zmqshell.py\", line 528, in run_cell\n      return super().run_cell(*args, **kwargs)\n    File \"/Users/omshah/.local/lib/python3.8/site-packages/IPython/core/interactiveshell.py\", line 2885, in run_cell\n      result = self._run_cell(\n    File \"/Users/omshah/.local/lib/python3.8/site-packages/IPython/core/interactiveshell.py\", line 2940, in _run_cell\n      return runner(coro)\n    File \"/Users/omshah/.local/lib/python3.8/site-packages/IPython/core/async_helpers.py\", line 129, in _pseudo_sync_runner\n      coro.send(None)\n    File \"/Users/omshah/.local/lib/python3.8/site-packages/IPython/core/interactiveshell.py\", line 3139, in run_cell_async\n      has_raised = await self.run_ast_nodes(code_ast.body, cell_name,\n    File \"/Users/omshah/.local/lib/python3.8/site-packages/IPython/core/interactiveshell.py\", line 3318, in run_ast_nodes\n      if await self.run_code(code, result, async_=asy):\n    File \"/Users/omshah/.local/lib/python3.8/site-packages/IPython/core/interactiveshell.py\", line 3378, in run_code\n      exec(code_obj, self.user_global_ns, self.user_ns)\n    File \"/var/folders/yw/3z56n_vx4vq9g05qrxzrr4m40000gn/T/ipykernel_19104/2308989814.py\", line 8, in <module>\n      consumption_predicts = trained_model.predict(test_batcher, steps=652)\n    File \"/Users/omshah/opt/anaconda3/envs/pypoverty38/lib/python3.8/site-packages/keras/utils/traceback_utils.py\", line 65, in error_handler\n      return fn(*args, **kwargs)\n    File \"/Users/omshah/opt/anaconda3/envs/pypoverty38/lib/python3.8/site-packages/keras/engine/training.py\", line 2253, in predict\n      tmp_batch_outputs = self.predict_function(iterator)\n    File \"/Users/omshah/opt/anaconda3/envs/pypoverty38/lib/python3.8/site-packages/keras/engine/training.py\", line 2041, in predict_function\n      return step_function(self, iterator)\n    File \"/Users/omshah/opt/anaconda3/envs/pypoverty38/lib/python3.8/site-packages/keras/engine/training.py\", line 2026, in step_function\n      data = next(iterator)\nNode: 'IteratorGetNext'\n2 root error(s) found.\n  (0) NOT_FOUND:  data/lsms_tfrecords/ethiopia_89_7.tfrecord; No such file or directory\n\t [[{{node IteratorGetNext}}]]\n\t [[IteratorGetNext/_2]]\n  (1) NOT_FOUND:  data/lsms_tfrecords/ethiopia_89_7.tfrecord; No such file or directory\n\t [[{{node IteratorGetNext}}]]\n0 successful operations.\n0 derived errors ignored. [Op:__inference_predict_function_10750]"
     ]
    }
   ],
   "source": [
    "# Get consumption predictions\n",
    "trained_model = load_model_from_dir(experiments[0])\n",
    "trained_model.compile(\n",
    "            loss=LOSS,\n",
    "            optimizer=OPT,\n",
    "            metrics=METRICS,\n",
    "        )\n",
    "consumption_predicts = trained_model.predict(test_batcher, steps=652)"
   ]
  },
  {
   "cell_type": "code",
   "execution_count": 60,
   "id": "0f8f633a",
   "metadata": {},
   "outputs": [
    {
     "ename": "NameError",
     "evalue": "name 'x' is not defined",
     "output_type": "error",
     "traceback": [
      "\u001b[0;31m---------------------------------------------------------------------------\u001b[0m",
      "\u001b[0;31mNameError\u001b[0m                                 Traceback (most recent call last)",
      "Cell \u001b[0;32mIn [60], line 2\u001b[0m\n\u001b[1;32m      1\u001b[0m \u001b[38;5;66;03m# Find r-squared\u001b[39;00m\n\u001b[0;32m----> 2\u001b[0m r2 \u001b[38;5;241m=\u001b[39m pearsonr(\u001b[43mx\u001b[49m, y)\n",
      "\u001b[0;31mNameError\u001b[0m: name 'x' is not defined"
     ]
    }
   ],
   "source": [
    "# Find r-squared\n",
    "r2 = pearsonr(x, y)"
   ]
  },
  {
   "cell_type": "code",
   "execution_count": null,
   "id": "11edc123",
   "metadata": {},
   "outputs": [],
   "source": [
    "# Plot predictions"
   ]
  }
 ],
 "metadata": {
  "kernelspec": {
   "display_name": "pypoverty38",
   "language": "python",
   "name": "pypoverty38"
  },
  "language_info": {
   "codemirror_mode": {
    "name": "ipython",
    "version": 3
   },
   "file_extension": ".py",
   "mimetype": "text/x-python",
   "name": "python",
   "nbconvert_exporter": "python",
   "pygments_lexer": "ipython3",
   "version": "3.8.15"
  }
 },
 "nbformat": 4,
 "nbformat_minor": 5
}
